try {
    x.catch();
} catch (x) {

}

foo.then(joinedCall).catch(function(error){})